Workbook
Name SelectedSmells: 'EA Smell Catalogue'!$C$58:$C$67
Name SmellCatalogue: 'EA Smell Catalogue'!$B$12:$E$18

Sheet Cover
B2: EA Smell Prioritization Tool
B4: AHP-Based Decision Support | Enterprise Architecture
B7: Project | C7: EA Smell Prioritisation Toolkit (AHP-Based Decision Support) | D7: v1.0
B8: Owner: | C8: Tolkounai K. | D8: 46252
B11: PURPOSE
B13: This tool applies the Analytic Hierarchy Process (AHP) to prioritize Enterprise Architecture (EA) smell instances identified during architectural reviews. It provides structured, multi-criteria evaluation with full consistency checking and scenario-based sensitivity analysis.
B16: HOW TO USE
B17: Step 1 | C17: 1.0 Case Context | D17: Define the decision context | E17: Read-Only
B18: Step 2 | C18: 1.1 AHP Hierarchy | D18: Review the AHP decision structure | E18: Read-Only
B19: Step 3 | C19: 1.2 Criteria Weights | D19: Set criteria importance | E19: User Input Required
B20: Step 4 | C20: 1.3 Intensity Priorities | D20: Set rating-level priorities | E20: Optional / Advanced Input
B21: Step 5 | C21: 1.4 EA Smell Scoring | D21: Rate EA smells against criteria | E21: User Input Required
B22: Step 6 | C22: 1.5 Results – EA Smell Dashboard | D22: Review prioritisation results | E22: Read-Only
B24: SHEET OVERVIEW
B25: Sheet | C25: Description | E25: Access
C26: 1.6 IP Calculations | D26: Review intensity priority calculations | E26: Optional / Read-Only
C27: 1.7 AHP Calculations | D27: Review criteria-weight calculations | E27: Optional / Read-Only
C28: EA Smell Catalogue | D28: Review and select EA smells | E28: Reference / Input
C29: AHP Saaty Reference | D29: Review the Saaty judgment scale | E29: Reference

Sheet 1.0 Case Context
D2: Case Context — Architecture Evidence
D5: ARCHIMATE MODEL
D6: #VALUE!
C9: SMELL EVIDENCE — Observations from the Architecture Model
C10: ID | D10: EA Smell | E10: Systems Involved | F10: Architectural Situation | G10: Observable Impact
C11: S1 | D11: Shared Persistency | E11: Salesforce CRM, SAP S/4HANA ERP, Power BI | F11: A shared central database is accessed by CRM, ERP, and Power BI, containing customer, order, invoice, and payment data. | G11: Changes to shared data structures require coordinated updates across multiple systems, introducing risks of data inconsistency and reducing system independence.
C12: S2 | D12: Feature Envy | E12: Salesforce CRM, SAP S/4HANA ERP | F12: The Customer Risk Assessment function in Salesforce CRM repeatedly accesses externally managed customer and financial data. | G12: Business logic becomes distributed across systems, increasing dependency on external data access and making changes harder to localize.
C13: S3 | D13: Cyclic Dependency | E13: Salesforce CRM, SAP S/4HANA ERP | F13: Salesforce CRM sends customer and order data to SAP S/4HANA ERP, while ERP returns invoice and payment status data to CRM, forming a bidirectional dependency. | G13: Independent modification, testing, or deployment of either system becomes difficult, as each system depends on the other’s outputs.
C14: S4 | D14: Stovepipe System | E14: Salesforce CRM, SAP S/4HANA ERP, Power BI | F14: Salesforce CRM, SAP S/4HANA ERP, and Power BI are integrated through system-specific data exchanges without a shared service abstraction layer. | G14: Integration logic is duplicated across system connections, reducing reusability and leading to brittle, hard-to-evolve integrations.
C15: S5 | D15: Vendor Lock-In | E15: SAP S/4HANA ERP, SAP Business Technology Platform | F15: Core enterprise processes and integration flows are implemented within the SAP ecosystem, including SAP S/4HANA ERP and SAP Business Technology Platform. | G15: Integration logic relies on SAP-specific technologies and platform services, increasing the effort required to migrate to alternative platforms or integration solutions.

Sheet 1.1 AHP Hierarchy
B2: AHP Hierarchy

Sheet 1.2 Weights
B2: Step 1 — Determine Criteria Importance (AHP Pairwise Comparisons)
B4: Select the pairwise judgment that best represents the relative importance between Criterion A and Criterion B. The AHP score is calculated automatically and should not be modified.
B6: Q# | C6: Question | D6: Criterion A | F6: Criterion B | G6: Pairwise Judgment | H6: AHP Score (calculated)
B8: SECTION 1 — Main Criteria
B9: Q1 | C9: With respect to prioritizing EA smell instances, which criterion is more important? | D9: Remediation Effort Remediation Effort (cost / effort to fix) | E9: vs | F9: Impact (architectural & operational impact) | G9: Equal importance (1) | H9: =IFERROR(_xlfn.XLOOKUP($G9,'AHP Saaty Reference'!$H$8:$H$24,'AHP Saaty Reference'!$I$8:$I$24),"") -> 1
B11: SECTION 2 — Remediation Effort Subcriteria
B12: Q2 | C12: With respect to remediation effort, which criterion is more important? | D12: Scope (number of affected elements) | E12: vs | F12: Restructuring Complexity (structural change effort) | G12: Equal importance (1) | H12: =IFERROR(_xlfn.XLOOKUP($G12,'AHP Saaty Reference'!$H$8:$H$24,'AHP Saaty Reference'!$I$8:$I$24),"") -> 1
B14: SECTION 3 — Impact Subcriteria
B15: Q5 | C15: With respect to impact, which criterion is more important? | D15: Evolution Constraint (architectural adaptability) | E15: vs | F15: Governance & Coordination Overhead (organizational complexity of change) | G15: Equal importance (1) | H15: =IFERROR(_xlfn.XLOOKUP($G15,'AHP Saaty Reference'!$H$8:$H$24,'AHP Saaty Reference'!$I$8:$I$24),"") -> 1
B16: Q6 | C16: With respect to impact, which criterion is more important? | D16: Evolution Constraint (architectural adaptability) | E16: vs | F16: Operational Reliability Impact (service disruption severity) | G16: Equal importance (1) | H16: =IFERROR(_xlfn.XLOOKUP($G16,'AHP Saaty Reference'!$H$8:$H$24,'AHP Saaty Reference'!$I$8:$I$24),"") -> 1
B17: Q7 | C17: With respect to impact, which criterion is more important? | D17: Governance & Coordination Overhead (organizational complexity of change) | E17: vs | F17: Operational Reliability Impact (service disruption severity) | G17: Equal importance (1) | H17: =IFERROR(_xlfn.XLOOKUP($G17,'AHP Saaty Reference'!$H$8:$H$24,'AHP Saaty Reference'!$I$8:$I$24),"") -> 1
B19: Step 2 — Check Consistency of Judgments
C21: Consistency Ratio (CR) – The consistency ratio evaluates the consistency of your pairwise judgments. A CR ≤ 0.10 indicates acceptable consistency. If the CR exceeds 0.10, revise your pairwise judgments. | F21: =IFERROR( IF('1.7 AHP Calculations'!C52<=0.1, "Acceptable"&CHAR(10)& "CR = "&TEXT('1.7 AHP Calculations'!C52,"0.000"), "Not Acceptable – Revise judgments"&CHAR(10)& "CR = "&TEXT('1.7 AHP Calculations'!C52,"0.000")), "Awaiting judgment inputs") -> Acceptable CR = 0.000
B23: Step 3 — Review Derived Criteria Weights
C25: Criterion | D25: Subcriterion | F25: Local Weight | G25: Global Weight
C26: Remediation Effort | F26: ='1.7 AHP Calculations'!$F$18 -> 0.5 | G26: ='1.2 Weights'!$F26 -> 0.5
D27: Scope | F27: ='1.7 AHP Calculations'!$D$60 -> 0.5 | G27: =F27*$F$26 -> 0.25
D28: Restructuring Complexity | F28: ='1.7 AHP Calculations'!$D$61 -> 0.5 | G28: =F28*$F$26 -> 0.25
C29: Impact | F29: ='1.7 AHP Calculations'!$F$19 -> 0.5 | G29: ='1.2 Weights'!$F29 -> 0.5
D30: Evolution Constraint | F30: ='1.7 AHP Calculations'!$D$62 -> 0.33333333 | G30: =F30*$F$29 -> 0.16666667
D31: Governance & Coordination Overhead | F31: ='1.7 AHP Calculations'!$D$63 -> 0.33333333 | G31: =F31*$F$29 -> 0.16666667
D32: Operational Reliability Impact | F32: ='1.7 AHP Calculations'!$D$64 -> 0.33333333 | G32: =F32*$F$29 -> 0.16666667

Sheet 1.3 IP Pairwise
B2: Intensity Priorities (AHP Pairwise Comparisons) - Advanced Input / Optional
B4: Pairwise judgments have been predefined based on the Level 1–5 progression. AHP scores are calculated automatically. Judgments may be adjusted to reflect a different decision context.
B8: Pair | C8: Criterion A | E8: Criterion B | F8: Pairwise Judgment | G8: AHP Score (calculated) | H8: Decision Rationale (Optional) | J8: ► (click +) | K8: Level | L8: Description | M8: Boundary Defintion | N8: Illustrative Example | S8: ► Column Helper
B10: Scope | J10: Scope ► | K10: How many architectural elements must change to eliminate this EA smell instance?
B12: Pair | C12: Criterion A | E12: Criterion B | F12: Pairwise Judgment | G12: AHP Score (calculated) | H12: Decision Rationale (Optional) | K12: Level | L12: Description | M12: Boundary Defintion | N12: Illustrative Example | T12: Pair | U12: A ID | V12: B ID
B13: 1 | C13: =_xlfn.XLOOKUP(_xlfn.XLOOKUP($B13,$T$13:$T$22,$U$13:$U$22),$K$13:$K$17,$K$13:$K$17)&" – "&_xlfn.XLOOKUP(_xlfn.XLOOKUP($B13,$T$13:$T$22,$U$13:$U$22),$K$13:$K$17,$L$13:$L$17) -> L1 – Single Element | D13: vs | E13: =_xlfn.XLOOKUP(_xlfn.XLOOKUP($B13,$T$13:$T$22,$V$13:$V$22),$K$13:$K$17,$K$13:$K$17)&" – "&_xlfn.XLOOKUP(_xlfn.XLOOKUP($B13,$T$13:$T$22,$V$13:$V$22),$K$13:$K$17,$L$13:$L$17) -> L2 – Single System | F13: Criterion A – Intermediate value between Equal and Moderate importance (2) | G13: =IFERROR(_xlfn.XLOOKUP($F13,'AHP Saaty Reference'!$H$8:$H$24,'AHP Saaty Reference'!$I$8:$I$24),"") -> 2 | H13: Scope increases, but remediation remains within a single system boundary. | K13: L1 | L13: Single Element | M13: Changes affect one architectural element only (e.g., component, service, or interface). | N13: In the CRM system, the Customer Service interface is incorrectly defined. Fixing the issue requires modifying only the Customer Service interface. | T13: 1 | U13: L1 | V13: L2
B14: 2 | C14: =_xlfn.XLOOKUP(_xlfn.XLOOKUP($B14,$T$13:$T$22,$U$13:$U$22),$K$13:$K$17,$K$13:$K$17)&" – "&_xlfn.XLOOKUP(_xlfn.XLOOKUP($B14,$T$13:$T$22,$U$13:$U$22),$K$13:$K$17,$L$13:$L$17) -> L1 – Single Element | D14: vs | E14: =_xlfn.XLOOKUP(_xlfn.XLOOKUP($B14,$T$13:$T$22,$V$13:$V$22),$K$13:$K$17,$K$13:$K$17)&" – "&_xlfn.XLOOKUP(_xlfn.XLOOKUP($B14,$T$13:$T$22,$V$13:$V$22),$K$13:$K$17,$L$13:$L$17) -> L3 – Multiple Systems (Limited Scope) | F14: Criterion A – Moderate importance (3) | G14: =IFERROR(_xlfn.XLOOKUP($F14,'AHP Saaty Reference'!$H$8:$H$24,'AHP Saaty Reference'!$I$8:$I$24),"") -> 3 | H14: The remediation expands from one element to multiple systems, creating a clear cross-system increase in scope. | K14: L2 | L14: Single System | M14: Changes affect multiple architectural elements within the same application/system boundary, but no other systems are involved. | N14: Within the ERP system, the Order Service is tightly coupled to the Inventory Service. Resolving the issue requires modifying both services within the ERP system. | T14: 2 | U14: L1 | V14: L3
B15: 3 | C15: =_xlfn.XLOOKUP(_xlfn.XLOOKUP($B15,$T$13:$T$22,$U$13:$U$22),$K$13:$K$17,$K$13:$K$17)&" – "&_xlfn.XLOOKUP(_xlfn.XLOOKUP($B15,$T$13:$T$22,$U$13:$U$22),$K$13:$K$17,$L$13:$L$17) -> L1 – Single Element | D15: vs | E15: =_xlfn.XLOOKUP(_xlfn.XLOOKUP($B15,$T$13:$T$22,$V$13:$V$22),$K$13:$K$17,$K$13:$K$17)&" – "&_xlfn.XLOOKUP(_xlfn.XLOOKUP($B15,$T$13:$T$22,$V$13:$V$22),$K$13:$K$17,$L$13:$L$17) -> L4 – Multiple Systems (Broad Scope) | F15: Criterion A – Strong importance (5) | G15: =IFERROR(_xlfn.XLOOKUP($F15,'AHP Saaty Reference'!$H$8:$H$24,'AHP Saaty Reference'!$I$8:$I$24),"") -> 5 | H15: The remediation spans multiple systems and multiple architectural element types, representing a strong increase over a single-element change. | K15: L3 | L15: Multiple Systems (Limited Scope) | M15: Changes affect multiple applications or systems, requiring modifications to a specific type of architectural element within each system (e.g., interfaces or services). | N15: The CRM and ERP systems exchange customer data through a poorly designed integration interface. Resolving the issue requires modifying the integration interfaces in both CRM and ERP systems. | T15: 3 | U15: L1 | V15: L4
B16: 4 | C16: =_xlfn.XLOOKUP(_xlfn.XLOOKUP($B16,$T$13:$T$22,$U$13:$U$22),$K$13:$K$17,$K$13:$K$17)&" – "&_xlfn.XLOOKUP(_xlfn.XLOOKUP($B16,$T$13:$T$22,$U$13:$U$22),$K$13:$K$17,$L$13:$L$17) -> L1 – Single Element | D16: vs | E16: =_xlfn.XLOOKUP(_xlfn.XLOOKUP($B16,$T$13:$T$22,$V$13:$V$22),$K$13:$K$17,$K$13:$K$17)&" – "&_xlfn.XLOOKUP(_xlfn.XLOOKUP($B16,$T$13:$T$22,$V$13:$V$22),$K$13:$K$17,$L$13:$L$17) -> L5 – Enterprise-Wide Scope | F16: Criterion A – Very strong importance (7) | G16: =IFERROR(_xlfn.XLOOKUP($F16,'AHP Saaty Reference'!$H$8:$H$24,'AHP Saaty Reference'!$I$8:$I$24),"") -> 7 | H16: Enterprise-wide shared architectural assets create a very large increase in scope compared with a single-element change. | K16: L4 | L16: Multiple Systems (Broad Scope) | M16: Changes affect multiple applications or systems and require modifications to multiple types of architectural elements within each system (e.g., services, interfaces, and data structures). | N16: The CRM and ERP systems are tightly coupled through multiple interacting components and data exchanges. Resolving the issue requires modifying components, interfaces, and data structures in both systems. | T16: 4 | U16: L1 | V16: L5
B17: 5 | C17: =_xlfn.XLOOKUP(_xlfn.XLOOKUP($B17,$T$13:$T$22,$U$13:$U$22),$K$13:$K$17,$K$13:$K$17)&" – "&_xlfn.XLOOKUP(_xlfn.XLOOKUP($B17,$T$13:$T$22,$U$13:$U$22),$K$13:$K$17,$L$13:$L$17) -> L2 – Single System | D17: vs | E17: =_xlfn.XLOOKUP(_xlfn.XLOOKUP($B17,$T$13:$T$22,$V$13:$V$22),$K$13:$K$17,$K$13:$K$17)&" – "&_xlfn.XLOOKUP(_xlfn.XLOOKUP($B17,$T$13:$T$22,$V$13:$V$22),$K$13:$K$17,$L$13:$L$17) -> L3 – Multiple Systems (Limited Scope) | F17: Criterion A – Moderate importance (3) | G17: =IFERROR(_xlfn.XLOOKUP($F17,'AHP Saaty Reference'!$H$8:$H$24,'AHP Saaty Reference'!$I$8:$I$24),"") -> 3 | H17: The scope expands from one system to multiple systems, introducing cross-system coordination. | K17: L5 | L17: Enterprise-Wide Scope | M17: Changes affect multiple systems or applications and require modifications to shared or common architectural elements used across systems (e.g., shared data models, integration platforms, or core services). | N17: Customer information is stored in a shared data model used by CRM, ERP, and Marketing systems. Resolving the issue requires modifying the shared data model, affecting all dependent systems. | T17: 5 | U17: L2 | V17: L3
B18: 6 | C18: =_xlfn.XLOOKUP(_xlfn.XLOOKUP($B18,$T$13:$T$22,$U$13:$U$22),$K$13:$K$17,$K$13:$K$17)&" – "&_xlfn.XLOOKUP(_xlfn.XLOOKUP($B18,$T$13:$T$22,$U$13:$U$22),$K$13:$K$17,$L$13:$L$17) -> L2 – Single System | D18: vs | E18: =_xlfn.XLOOKUP(_xlfn.XLOOKUP($B18,$T$13:$T$22,$V$13:$V$22),$K$13:$K$17,$K$13:$K$17)&" – "&_xlfn.XLOOKUP(_xlfn.XLOOKUP($B18,$T$13:$T$22,$V$13:$V$22),$K$13:$K$17,$L$13:$L$17) -> L4 – Multiple Systems (Broad Scope) | F18: Criterion A – Strong importance (5) | G18: =IFERROR(_xlfn.XLOOKUP($F18,'AHP Saaty Reference'!$H$8:$H$24,'AHP Saaty Reference'!$I$8:$I$24),"") -> 5 | H18: L4 expands beyond one system and affects multiple architectural element types across systems. | T18: 6 | U18: L2 | V18: L4
B19: 7 | C19: =_xlfn.XLOOKUP(_xlfn.XLOOKUP($B19,$T$13:$T$22,$U$13:$U$22),$K$13:$K$17,$K$13:$K$17)&" – "&_xlfn.XLOOKUP(_xlfn.XLOOKUP($B19,$T$13:$T$22,$U$13:$U$22),$K$13:$K$17,$L$13:$L$17) -> L2 – Single System | D19: vs | E19: =_xlfn.XLOOKUP(_xlfn.XLOOKUP($B19,$T$13:$T$22,$V$13:$V$22),$K$13:$K$17,$K$13:$K$17)&" – "&_xlfn.XLOOKUP(_xlfn.XLOOKUP($B19,$T$13:$T$22,$V$13:$V$22),$K$13:$K$17,$L$13:$L$17) -> L5 – Enterprise-Wide Scope | F19: Criterion A – Very strong importance (7) | G19: =IFERROR(_xlfn.XLOOKUP($F19,'AHP Saaty Reference'!$H$8:$H$24,'AHP Saaty Reference'!$I$8:$I$24),"") -> 7 | H19: The scope moves from a single-system change to shared enterprise architecture affecting dependent systems across the organization. | T19: 7 | U19: L2 | V19: L5
B20: 8 | C20: =_xlfn.XLOOKUP(_xlfn.XLOOKUP($B20,$T$13:$T$22,$U$13:$U$22),$K$13:$K$17,$K$13:$K$17)&" – "&_xlfn.XLOOKUP(_xlfn.XLOOKUP($B20,$T$13:$T$22,$U$13:$U$22),$K$13:$K$17,$L$13:$L$17) -> L3 – Multiple Systems (Limited Scope) | D20: vs | E20: =_xlfn.XLOOKUP(_xlfn.XLOOKUP($B20,$T$13:$T$22,$V$13:$V$22),$K$13:$K$17,$K$13:$K$17)&" – "&_xlfn.XLOOKUP(_xlfn.XLOOKUP($B20,$T$13:$T$22,$V$13:$V$22),$K$13:$K$17,$L$13:$L$17) -> L4 – Multiple Systems (Broad Scope) | F20: Criterion A – Intermediate value between Equal and Moderate importance (2) | G20: =IFERROR(_xlfn.XLOOKUP($F20,'AHP Saaty Reference'!$H$8:$H$24,'AHP Saaty Reference'!$I$8:$I$24),"") -> 2 | H20: Both affect multiple systems, but L4 requires modifications to a broader range of architectural element types. | T20: 8 | U20: L3 | V20: L4
B21: 9 | C21: =_xlfn.XLOOKUP(_xlfn.XLOOKUP($B21,$T$13:$T$22,$U$13:$U$22),$K$13:$K$17,$K$13:$K$17)&" – "&_xlfn.XLOOKUP(_xlfn.XLOOKUP($B21,$T$13:$T$22,$U$13:$U$22),$K$13:$K$17,$L$13:$L$17) -> L3 – Multiple Systems (Limited Scope) | D21: vs | E21: =_xlfn.XLOOKUP(_xlfn.XLOOKUP($B21,$T$13:$T$22,$V$13:$V$22),$K$13:$K$17,$K$13:$K$17)&" – "&_xlfn.XLOOKUP(_xlfn.XLOOKUP($B21,$T$13:$T$22,$V$13:$V$22),$K$13:$K$17,$L$13:$L$17) -> L5 – Enterprise-Wide Scope | F21: Criterion A – Strong importance (5) | G21: =IFERROR(_xlfn.XLOOKUP($F21,'AHP Saaty Reference'!$H$8:$H$24,'AHP Saaty Reference'!$I$8:$I$24),"") -> 5 | H21: L5 affects shared enterprise assets and their dependent systems, substantially exceeding limited multi-system scope. | T21: 9 | U21: L3 | V21: L5
B22: 10 | C22: =_xlfn.XLOOKUP(_xlfn.XLOOKUP($B22,$T$13:$T$22,$U$13:$U$22),$K$13:$K$17,$K$13:$K$17)&" – "&_xlfn.XLOOKUP(_xlfn.XLOOKUP($B22,$T$13:$T$22,$U$13:$U$22),$K$13:$K$17,$L$13:$L$17) -> L4 – Multiple Systems (Broad Scope) | D22: vs | E22: =_xlfn.XLOOKUP(_xlfn.XLOOKUP($B22,$T$13:$T$22,$V$13:$V$22),$K$13:$K$17,$K$13:$K$17)&" – "&_xlfn.XLOOKUP(_xlfn.XLOOKUP($B22,$T$13:$T$22,$V$13:$V$22),$K$13:$K$17,$L$13:$L$17) -> L5 – Enterprise-Wide Scope | F22: Criterion A – Strong importance (5) | G22: =IFERROR(_xlfn.XLOOKUP($F22,'AHP Saaty Reference'!$H$8:$H$24,'AHP Saaty Reference'!$I$8:$I$24),"") -> 5 | H22: L5 shifts the remediation from broad multi-system changes to shared enterprise architecture with wider dependency propagation. | T22: 10 | U22: L4 | V22: L5
B24: Consistency Ratio (CR) – The consistency ratio evaluates the consistency of your pairwise judgments. A CR ≤ 0.10 indicates acceptable consistency. If the CR exceeds 0.10, revise your pairwise judgments. | G24: =IF( '1.6 IP Calculations'!$C$52="", "Awaiting judgment inputs", IF( '1.6 IP Calculations'!$C$52<=0.1, "Acceptable"&CHAR(10)&"CR = "&TEXT('1.6 IP Calculations'!$C$52,"0.000"), "Not Acceptable – Revise judgments"&CHAR(10)&"CR = "&TEXT('1.6 IP Calculations'!$C$52,"0.000") ) ) -> Acceptable CR = 0.059
B26: Calculated Results Derived Intensity Priorities (Priority Vector)
B28: The priority vector is derived from the pairwise comparisons using the Analytic Hierarchy Process (AHP). Idealized priorities are obtained by dividing each priority by the largest priority, resulting in a maximum value of 1.000. These idealized priorities are automatically used during EA smell scoring.
B31: Level | C31: Idealized Priority
B32: L1 | C32: =IF(OR('1.6 IP Calculations'!$D26="",ISBLANK('1.6 IP Calculations'!$D26)),"Awaiting input",'1.6 IP Calculations'!$D26) -> 1
B33: L2 | C33: =IF(OR('1.6 IP Calculations'!$D27="",ISBLANK('1.6 IP Calculations'!$D27)),"Awaiting input",'1.6 IP Calculations'!$D27) -> 0.76050351
B34: L3 | C34: =IF(OR('1.6 IP Calculations'!$D28="",ISBLANK('1.6 IP Calculations'!$D28)),"Awaiting input",'1.6 IP Calculations'!$D28) -> 0.34263524
B35: L4 | C35: =IF(OR('1.6 IP Calculations'!$D29="",ISBLANK('1.6 IP Calculations'!$D29)),"Awaiting input",'1.6 IP Calculations'!$D29) -> 0.22309669
B36: L5 | C36: =IF(OR('1.6 IP Calculations'!$D30="",ISBLANK('1.6 IP Calculations'!$D30)),"Awaiting input",'1.6 IP Calculations'!$D30) -> 0.085534816
B39: Restructuring Complexity | J39: Restructuring Complexity ► | K39: How structurally difficult is it to remove this EA smell instance from the architecture?
B41: Pair | C41: Criterion A | E41: Criterion B | F41: Pairwise Judgment | G41: AHP Score (calculated) | H41: Decision Rationale (Optional) | K41: Level | L41: Description | M41: Boundary Defintion | N41: Representative Refactoring Types (derived from Liss et al.)
B42: 1 | C42: =_xlfn.XLOOKUP(_xlfn.XLOOKUP($B42,$T$13:$T$22,$U$13:$U$22),$K$42:$K$46,$K$42:$K$46)&" – "&_xlfn.XLOOKUP(_xlfn.XLOOKUP($B42,$T$13:$T$22,$U$13:$U$22),$K$42:$K$46,$L$42:$L$46) -> L1 – Minor Architectural Adjustment | D42: vs | E42: =_xlfn.XLOOKUP(_xlfn.XLOOKUP($B42,$T$13:$T$22,$V$13:$V$22),$K$42:$K$46,$K$42:$K$46)&" – "&_xlfn.XLOOKUP(_xlfn.XLOOKUP($B42,$T$13:$T$22,$V$13:$V$22),$K$42:$K$46,$L$42:$L$46) -> L2 – Local Component Modification | F42: Criterion A – Intermediate value between Equal and Moderate importance (2) | G42: =IFERROR(_xlfn.XLOOKUP($F42,'AHP Saaty Reference'!$H$8:$H$24,'AHP Saaty Reference'!$I$8:$I$24),"") -> 2 | H42: The remediation expands from one element to multiple systems, creating a clear cross-system increase in scope. | K42: L1 | L42: Minor Architectural Adjustment | M42: Small changes to architectural elements that do not alter component responsibilities or the overall architectural structure. | N42: Rename Component
B43: 2 | C43: =_xlfn.XLOOKUP(_xlfn.XLOOKUP($B43,$T$13:$T$22,$U$13:$U$22),$K$42:$K$46,$K$42:$K$46)&" – "&_xlfn.XLOOKUP(_xlfn.XLOOKUP($B43,$T$13:$T$22,$U$13:$U$22),$K$42:$K$46,$L$42:$L$46) -> L1 – Minor Architectural Adjustment | D43: vs | E43: =_xlfn.XLOOKUP(_xlfn.XLOOKUP($B43,$T$13:$T$22,$V$13:$V$22),$K$42:$K$46,$K$42:$K$46)&" – "&_xlfn.XLOOKUP(_xlfn.XLOOKUP($B43,$T$13:$T$22,$V$13:$V$22),$K$42:$K$46,$L$42:$L$46) -> L3 – Component Restructuring (Single System) | F43: Criterion A – Moderate importance (3) | G43: =IFERROR(_xlfn.XLOOKUP($F43,'AHP Saaty Reference'!$H$8:$H$24,'AHP Saaty Reference'!$I$8:$I$24),"") -> 3 | H43: L3 reorganizes component responsibilities and interactions within a system, whereas L1 is limited to minor architectural adjustments. | K43: L2 | L43: Local Component Modification | M43: Changes affecting a single architectural component without altering how the architecture is organized or relationships between components. | N43: Remove Dead Component, Inline Service
B44: 3 | C44: =_xlfn.XLOOKUP(_xlfn.XLOOKUP($B44,$T$13:$T$22,$U$13:$U$22),$K$42:$K$46,$K$42:$K$46)&" – "&_xlfn.XLOOKUP(_xlfn.XLOOKUP($B44,$T$13:$T$22,$U$13:$U$22),$K$42:$K$46,$L$42:$L$46) -> L1 – Minor Architectural Adjustment | D44: vs | E44: =_xlfn.XLOOKUP(_xlfn.XLOOKUP($B44,$T$13:$T$22,$V$13:$V$22),$K$42:$K$46,$K$42:$K$46)&" – "&_xlfn.XLOOKUP(_xlfn.XLOOKUP($B44,$T$13:$T$22,$V$13:$V$22),$K$42:$K$46,$L$42:$L$46) -> L4 – Architectural Reorganization | F44: Criterion A – Strong importance (5) | G44: =IFERROR(_xlfn.XLOOKUP($F44,'AHP Saaty Reference'!$H$8:$H$24,'AHP Saaty Reference'!$I$8:$I$24),"") -> 5 | H44: L4 reorganizes architectural relationships across system boundaries, whereas L1 involves only minor local architectural adjustments. | K44: L3 | L44: Component Restructuring (Single System) | M44: Refactoring that reorganizes responsibilities between architectural components within the same system, modifying component interactions while preserving the overall system structure. | N44: Break Up Component, Extract Component, Merge Components
B45: 4 | C45: =_xlfn.XLOOKUP(_xlfn.XLOOKUP($B45,$T$13:$T$22,$U$13:$U$22),$K$42:$K$46,$K$42:$K$46)&" – "&_xlfn.XLOOKUP(_xlfn.XLOOKUP($B45,$T$13:$T$22,$U$13:$U$22),$K$42:$K$46,$L$42:$L$46) -> L1 – Minor Architectural Adjustment | D45: vs | E45: =_xlfn.XLOOKUP(_xlfn.XLOOKUP($B45,$T$13:$T$22,$V$13:$V$22),$K$42:$K$46,$K$42:$K$46)&" – "&_xlfn.XLOOKUP(_xlfn.XLOOKUP($B45,$T$13:$T$22,$V$13:$V$22),$K$42:$K$46,$L$42:$L$46) -> L5 – Architectural Layer Restructuring | F45: Criterion A – Very strong importance (7) | G45: =IFERROR(_xlfn.XLOOKUP($F45,'AHP Saaty Reference'!$H$8:$H$24,'AHP Saaty Reference'!$I$8:$I$24),"") -> 7 | H45: L5 fundamentally restructures architectural layers and the overall architecture, whereas L1 is limited to minor architectural adjustments. | K45: L4 | L45: Architectural Reorganization | M45: Refactoring that reorganizes architectural relationships between systems, requiring changes to how components interact across system boundaries and altering integration structures. | N45: Move Component, Reorganization
B46: 5 | C46: =_xlfn.XLOOKUP(_xlfn.XLOOKUP($B46,$T$13:$T$22,$U$13:$U$22),$K$42:$K$46,$K$42:$K$46)&" – "&_xlfn.XLOOKUP(_xlfn.XLOOKUP($B46,$T$13:$T$22,$U$13:$U$22),$K$42:$K$46,$L$42:$L$46) -> L2 – Local Component Modification | D46: vs | E46: =_xlfn.XLOOKUP(_xlfn.XLOOKUP($B46,$T$13:$T$22,$V$13:$V$22),$K$42:$K$46,$K$42:$K$46)&" – "&_xlfn.XLOOKUP(_xlfn.XLOOKUP($B46,$T$13:$T$22,$V$13:$V$22),$K$42:$K$46,$L$42:$L$46) -> L3 – Component Restructuring (Single System) | F46: Criterion A – Intermediate value between Equal and Moderate importance (2) | G46: =IFERROR(_xlfn.XLOOKUP($F46,'AHP Saaty Reference'!$H$8:$H$24,'AHP Saaty Reference'!$I$8:$I$24),"") -> 2 | H46: L3 reorganizes responsibilities between architectural components, whereas L2 modifies only a single architectural component. | K46: L5 | L46: Architectural Layer Restructuring | M46: Refactoring that introduces, removes, or fundamentally restructures architectural layers or abstraction structures, significantly altering the overall architecture. | N46: Isolation Layer, Move Service to Different Layer
B47: 6 | C47: =_xlfn.XLOOKUP(_xlfn.XLOOKUP($B47,$T$13:$T$22,$U$13:$U$22),$K$42:$K$46,$K$42:$K$46)&" – "&_xlfn.XLOOKUP(_xlfn.XLOOKUP($B47,$T$13:$T$22,$U$13:$U$22),$K$42:$K$46,$L$42:$L$46) -> L2 – Local Component Modification | D47: vs | E47: =_xlfn.XLOOKUP(_xlfn.XLOOKUP($B47,$T$13:$T$22,$V$13:$V$22),$K$42:$K$46,$K$42:$K$46)&" – "&_xlfn.XLOOKUP(_xlfn.XLOOKUP($B47,$T$13:$T$22,$V$13:$V$22),$K$42:$K$46,$L$42:$L$46) -> L4 – Architectural Reorganization | F47: Criterion A – Strong importance (5) | G47: =IFERROR(_xlfn.XLOOKUP($F47,'AHP Saaty Reference'!$H$8:$H$24,'AHP Saaty Reference'!$I$8:$I$24),"") -> 5 | H47: L4 reorganizes cross-system architectural relationships and integration structures, whereas L2 modifies only a single architectural component.
B48: 7 | C48: =_xlfn.XLOOKUP(_xlfn.XLOOKUP($B48,$T$13:$T$22,$U$13:$U$22),$K$42:$K$46,$K$42:$K$46)&" – "&_xlfn.XLOOKUP(_xlfn.XLOOKUP($B48,$T$13:$T$22,$U$13:$U$22),$K$42:$K$46,$L$42:$L$46) -> L2 – Local Component Modification | D48: vs | E48: =_xlfn.XLOOKUP(_xlfn.XLOOKUP($B48,$T$13:$T$22,$V$13:$V$22),$K$42:$K$46,$K$42:$K$46)&" – "&_xlfn.XLOOKUP(_xlfn.XLOOKUP($B48,$T$13:$T$22,$V$13:$V$22),$K$42:$K$46,$L$42:$L$46) -> L5 – Architectural Layer Restructuring | F48: Criterion A – Very strong importance (7) | G48: =IFERROR(_xlfn.XLOOKUP($F48,'AHP Saaty Reference'!$H$8:$H$24,'AHP Saaty Reference'!$I$8:$I$24),"") -> 7 | H48: L5 fundamentally restructures architectural layers, whereas L2 modifies only a single architectural component.
B49: 8 | C49: =_xlfn.XLOOKUP(_xlfn.XLOOKUP($B49,$T$13:$T$22,$U$13:$U$22),$K$42:$K$46,$K$42:$K$46)&" – "&_xlfn.XLOOKUP(_xlfn.XLOOKUP($B49,$T$13:$T$22,$U$13:$U$22),$K$42:$K$46,$L$42:$L$46) -> L3 – Component Restructuring (Single System) | D49: vs | E49: =_xlfn.XLOOKUP(_xlfn.XLOOKUP($B49,$T$13:$T$22,$V$13:$V$22),$K$42:$K$46,$K$42:$K$46)&" – "&_xlfn.XLOOKUP(_xlfn.XLOOKUP($B49,$T$13:$T$22,$V$13:$V$22),$K$42:$K$46,$L$42:$L$46) -> L4 – Architectural Reorganization | F49: Criterion A – Strong importance (5) | G49: =IFERROR(_xlfn.XLOOKUP($F49,'AHP Saaty Reference'!$H$8:$H$24,'AHP Saaty Reference'!$I$8:$I$24),"") -> 5 | H49: L4 reorganizes cross-system interactions and integration structures, whereas L3 restructures components only within a single system.
B50: 9 | C50: =_xlfn.XLOOKUP(_xlfn.XLOOKUP($B50,$T$13:$T$22,$U$13:$U$22),$K$42:$K$46,$K$42:$K$46)&" – "&_xlfn.XLOOKUP(_xlfn.XLOOKUP($B50,$T$13:$T$22,$U$13:$U$22),$K$42:$K$46,$L$42:$L$46) -> L3 – Component Restructuring (Single System) | D50: vs | E50: =_xlfn.XLOOKUP(_xlfn.XLOOKUP($B50,$T$13:$T$22,$V$13:$V$22),$K$42:$K$46,$K$42:$K$46)&" – "&_xlfn.XLOOKUP(_xlfn.XLOOKUP($B50,$T$13:$T$22,$V$13:$V$22),$K$42:$K$46,$L$42:$L$46) -> L5 – Architectural Layer Restructuring | F50: Criterion A – Strong importance (5) | G50: =IFERROR(_xlfn.XLOOKUP($F50,'AHP Saaty Reference'!$H$8:$H$24,'AHP Saaty Reference'!$I$8:$I$24),"") -> 5 | H50: L5 fundamentally restructures architectural layers, whereas L3 restructures component responsibilities within a single system.
B51: 10 | C51: =_xlfn.XLOOKUP(_xlfn.XLOOKUP($B51,$T$13:$T$22,$U$13:$U$22),$K$42:$K$46,$K$42:$K$46)&" – "&_xlfn.XLOOKUP(_xlfn.XLOOKUP($B51,$T$13:$T$22,$U$13:$U$22),$K$42:$K$46,$L$42:$L$46) -> L4 – Architectural Reorganization | D51: vs | E51: =_xlfn.XLOOKUP(_xlfn.XLOOKUP($B51,$T$13:$T$22,$V$13:$V$22),$K$42:$K$46,$K$42:$K$46)&" – "&_xlfn.XLOOKUP(_xlfn.XLOOKUP($B51,$T$13:$T$22,$V$13:$V$22),$K$42:$K$46,$L$42:$L$46) -> L5 – Architectural Layer Restructuring | F51: Criterion A – Strong importance (5) | G51: =IFERROR(_xlfn.XLOOKUP($F51,'AHP Saaty Reference'!$H$8:$H$24,'AHP Saaty Reference'!$I$8:$I$24),"") -> 5 | H51: L5 fundamentally restructures the architectural layers, whereas L4 reorganizes relationships between systems while preserving the overall architectural structure.
B53: Consistency Ratio (CR) – The consistency ratio evaluates the consistency of your pairwise judgments. A CR ≤ 0.10 indicates acceptable consistency. If the CR exceeds 0.10, revise your pairwise judgments. | G53: =IF( '1.6 IP Calculations'!$M$52="", "Awaiting judgment inputs", IF( '1.6 IP Calculations'!$M$52<=0.1, "Acceptable"&CHAR(10)&"CR = "&TEXT('1.6 IP Calculations'!$M$52,"0.000"), "Not Acceptable – Revise judgments"&CHAR(10)&"CR = "&TEXT('1.6 IP Calculations'!$M$52,"0.000") ) ) -> Acceptable CR = 0.088
B55: Calculated Results Derived Intensity Priorities (Priority Vector)
B57: The priority vector is derived from the pairwise comparisons using the Analytic Hierarchy Process (AHP). Idealized priorities are obtained by dividing each priority by the largest priority, resulting in a maximum value of 1.000. These idealized priorities are automatically used during EA smell scoring.
B60: Level | C60: Idealized Priority
...

Sheet 1.4 EA Smell Scoring
B2: Step 3 — EA Smell Scoring Matrix | K2: Scoring Guidance
B4: Instructions: Select up to 10 EA smells in the EA Smell Catalogue sheet, then assign each selected smell a 1–5 rating for every subcriterion using the reference panels on the right [+]. Ratings are entered once and reused across all weighting scenarios; only the criteria weights vary. | K4: Scope ► (click +) | L4: How many architectural elements must change to eliminate this EA smell instance? | P4: Restructuring Complexity ► (click +) | Q4: How structurally difficult is it to remove this EA smell instance from the architecture? | U4: Evolution Constraint ► (click +) | V4: To what extent does the EA smell instance limit the architecture’s ability to evolve or change? | Z4: Gov. & Coord. Overhead ► (click +) | AA4: To what extent does the EA smell instance require coordination across teams or governance bodies? | AE4: Operational Reliability Impact ► (click +) | AF4: To what extent does the EA smell instance negatively affect system reliability or stability of operations?
B6: Go to EA Smell Catalogue → | D6: User Input ↓ Select a rating (1–5) for each subcriterion | K6: Subcriterion definitons are maintained in the Pairwise: Intensity Priorities sheet. Do NOT modify in this sheet.
B7: # | C7: EA Smell | D7: Remediation Effort | F7: Impact | I7: Notes
D8: Scope | E8: Restructuring Complexity | F8: Evolution Constraint | G8: Governance Overhead | H8: Reliability Impact | L8: Level | M8: Boundary Definition | N8: Illustrative Example | Q8: Level | R8: Boundary Definition | S8: Representative Refactoring Types (derived from Liss et al.) | V8: Level | W8: Boundary Definition | X8: Illustrative Example | AA8: Level | AB8: Boundary Definition | AC8: Illustrative Example | AF8: Level | AG8: Boundary Definition | AH8: Illustrative Example
B9: 1 | C9: Cyclic Dependency | D9: 4 | E9: 4 | F9: 4 | G9: 3 | H9: 3 | I9: Mutual dependencies across components increase restructuring complexity and significantly constrain independent evolution. | L9: =_xlfn.CONCAT('1.3 IP Pairwise'!K13," ","-"," ",'1.3 IP Pairwise'!L13) -> L1 - Single Element | M9: ='1.3 IP Pairwise'!M13 -> Changes affect one architectural element only (e.g., component, service, or interface). | N9: ='1.3 IP Pairwise'!N13 -> In the CRM system, the Customer Service interface is incorrectly defined. Fixing the issue requires modifying only the Customer Service interface. | Q9: =_xlfn.CONCAT('1.3 IP Pairwise'!K42," ","-"," ",'1.3 IP Pairwise'!L42) -> L1 - Minor Architectural Adjustment | R9: ='1.3 IP Pairwise'!M42 -> Small changes to architectural elements that do not alter component responsibilities or the overall architectural structure. | S9: ='1.3 IP Pairwise'!N42 -> Rename Component | V9: =_xlfn.CONCAT('1.3 IP Pairwise'!K71," ","-"," ",'1.3 IP Pairwise'!L71) -> L1 - No Constraint | W9: ='1.3 IP Pairwise'!M71 -> The EA smell does not introduce constraints on how changes to architectural elements can be implemented. Changes can be implemented without restrictions on technology choice, integration approach, or application structure. | X9: ='1.3 IP Pairwise'!N71 -> A duplicate reporting application exists but does not affect other systems; removing or keeping it does not restrict how changes to the architecture can be implemented. | AA9: =_xlfn.CONCAT('1.3 IP Pairwise'!K100," ","-"," ",'1.3 IP Pairwise'!L100) -> L1 - Minimal Coordination Overhead | AB9: ='1.3 IP Pairwise'!M100 -> The EA-smell instance creates little or no coordination dependency beyond a single stakeholder group. | AC9: ='1.3 IP Pairwise'!N100 -> Duplicate functionality exists in the ERP and payroll systems for calculating timesheets. A business analyst identifies the redundancy and redesigns the business process so that timesheet calculation is performed only in the ERP system. The architectural condition is confined to the responsibility of a single stakeholder group and does not create coordination dependencies with other teams. | AF9: =_xlfn.CONCAT('1.3 IP Pairwise'!K129," ","-"," ",'1.3 IP Pairwise'!L129) -> L1 - No Impact | AG9: ='1.3 IP Pairwise'!M129 -> No failures or disruptions are observed that can be associated with the EA smell. System operation remains stable, with no incident records or logs indicating operational issues. | AH9: ='1.3 IP Pairwise'!N129 -> An EA smell is identified in the architecture, but no incidents, errors, or operational anomalies have been reported, and all services continue to operate as expected.
B10: 2 | C10: Shared Persistency | D10: 5 | E10: 3 | F10: 5 | G10: 4 | H10: 4 | I10: Shared Persistency was scored with high scope and evolution constraint due to its cross-system impact and tight data coupling, while restructuring complexity was assessed as moderate given the availability of established architectural refactoring approaches. | L10: =_xlfn.CONCAT('1.3 IP Pairwise'!K14," ","-"," ",'1.3 IP Pairwise'!L14) -> L2 - Single System | M10: ='1.3 IP Pairwise'!M14 -> Changes affect multiple architectural elements within the same application/system boundary, but no other systems are involved. | N10: ='1.3 IP Pairwise'!N14 -> Within the ERP system, the Order Service is tightly coupled to the Inventory Service. Resolving the issue requires modifying both services within the ERP system. | Q10: =_xlfn.CONCAT('1.3 IP Pairwise'!K43," ","-"," ",'1.3 IP Pairwise'!L43) -> L2 - Local Component Modification | R10: ='1.3 IP Pairwise'!M43 -> Changes affecting a single architectural component without altering how the architecture is organized or relationships between components. | S10: ='1.3 IP Pairwise'!N43 -> Remove Dead Component, Inline Service | V10: =_xlfn.CONCAT('1.3 IP Pairwise'!K72," ","-"," ",'1.3 IP Pairwise'!L72) -> L2 - Minor Constraint | W10: ='1.3 IP Pairwise'!M72 -> The EA smell introduces a localized constraint to a single architectural element (e.g., a component, service, or interface). Changes are restricted to specific implementation choices within that element (e.g., fixed technology, configuration, or interface definition), while the overall architecture remains adaptable, allowing new systems, components, or integrations to be introduced without restriction. | X10: ='1.3 IP Pairwise'!N72 -> An application uses a hard coded configuration for an external service endpoint. Changing the configuration requires modifying the application, but no other architectural elements are affected, and the overall architecture remains flexible. | AA10: =_xlfn.CONCAT('1.3 IP Pairwise'!K101," ","-"," ",'1.3 IP Pairwise'!L101) -> L2 - Limited Coordination Overhead | AB10: ='1.3 IP Pairwise'!M101 -> The EA-smell instance creates coordination dependencies between two stakeholder groups. | AC10: ='1.3 IP Pairwise'!N101 -> Duplicate functionality exists in the ERP and payroll systems for calculating timesheets. A business analyst decides that timesheet calculation should be performed only in the ERP system. Developers introduce a simple application interface through which the payroll system imports the calculated timesheets from the ERP system. The dependency between the two systems creates a coordination requirement between business stakeholders and application developers. | AF10: =_xlfn.CONCAT('1.3 IP Pairwise'!K130," ","-"," ",'1.3 IP Pairwise'!L130) -> L2 - Minor Impact | AG10: ='1.3 IP Pairwise'!M130 -> Issues associated with the EA smell may be observable in logs or low-priority events but do not affect system operation. These issues are resolved automatically through built-in mechanisms and do not require manual operational intervention. | AH10: ='1.3 IP Pairwise'!N130 -> Occasional errors related to the EA smell are recorded in system logs but are resolved through retry or fallback mechanisms, and services continue to operate without interruption or user impact.
B11: 3 | C11: Feature Envy | D11: 3 | E11: 3 | F11: 3 | G11: 2 | H11: 2 | I11: A localized design issue causing moderate refactoring effort, with limited scope and low impact on coordination and system reliability. | L11: =_xlfn.CONCAT('1.3 IP Pairwise'!K15," ","-"," ",'1.3 IP Pairwise'!L15) -> L3 - Multiple Systems (Limited Scope) | M11: ='1.3 IP Pairwise'!M15 -> Changes affect multiple applications or systems, requiring modifications to a specific type of architectural element within each system (e.g., interfaces or services). | N11: ='1.3 IP Pairwise'!N15 -> The CRM and ERP systems exchange customer data through a poorly designed integration interface. Resolving the issue requires modifying the integration interfaces in both CRM and ERP systems. | Q11: =_xlfn.CONCAT('1.3 IP Pairwise'!K44," ","-"," ",'1.3 IP Pairwise'!L44) -> L3 - Component Restructuring (Single System) | R11: ='1.3 IP Pairwise'!M44 -> Refactoring that reorganizes responsibilities between architectural components within the same system, modifying component interactions while preserving the overall system structure. | S11: ='1.3 IP Pairwise'!N44 -> Break Up Component, Extract Component, Merge Components | V11: =_xlfn.CONCAT('1.3 IP Pairwise'!K73," ","-"," ",'1.3 IP Pairwise'!L73) -> L3 - Moderate Constraint | W11: ='1.3 IP Pairwise'!M73 -> The EA smell introduces dependency-driven constraints between architectural elements. Changes to one architectural element require updates to directly dependent architectural elements (e.g., modifying an interface requires updating components that use that interface); however, the impact remains limited to a single level of dependency and does not propagate further. | X11: ='1.3 IP Pairwise'!N73 -> The CRM system exposes an interface consumed by the ERP system. Modifying the interface (e.g., changing required data fields) requires updating the ERP system to maintain compatibility, but no further elements are affected. | AA11: =_xlfn.CONCAT('1.3 IP Pairwise'!K102," ","-"," ",'1.3 IP Pairwise'!L102) -> L3 - Moderate Coordination Overhead | AB11: ='1.3 IP Pairwise'!M102 -> The EA-smell instance creates coordination dependencies across multiple stakeholder groups. | AC11: ='1.3 IP Pairwise'!N102 -> Duplicate functionality exists in the ERP and payroll systems for calculating timesheets. A business analyst decides that timesheet calculation should be performed only in the ERP system. Developers introduce an application interface for importing the timesheets, while the infrastructure team configures an automated job scheduler to execute the transfer between systems. The resulting dependencies create coordination requirements among business stakeholders, developers, and infrastructure teams. | AF11: =_xlfn.CONCAT('1.3 IP Pairwise'!K131," ","-"," ",'1.3 IP Pairwise'!L131) -> L3 - Moderate Impact | AG11: ='1.3 IP Pairwise'!M131 -> Failures associated with the EA smell cause a noticeable but localized disruption to system operation and require manual operational intervention to resolve. The impact remains confined to a single component or service and does not degrade business-critical capabilities. | AH11: ='1.3 IP Pairwise'!N131 -> An incident associated with the EA smell results in a localized disruption to a single component or service, requiring manual intervention (e.g., restart or correction), while business-critical capabilities continue to operate normally.
B12: 4 | C12: Stovepipe System | D12: 4 | E12: 4 | F12: 4 | G12: 3 | H12: 4 | I12: Siloed systems require substantial integration effort, limiting architectural flexibility and affecting operational consistency. | L12: =_xlfn.CONCAT('1.3 IP Pairwise'!K16," ","-"," ",'1.3 IP Pairwise'!L16) -> L4 - Multiple Systems (Broad Scope) | M12: ='1.3 IP Pairwise'!M16 -> Changes affect multiple applications or systems and require modifications to multiple types of architectural elements within each system (e.g., services, interfaces, and data structures). | N12: ='1.3 IP Pairwise'!N16 -> The CRM and ERP systems are tightly coupled through multiple interacting components and data exchanges. Resolving the issue requires modifying components, interfaces, and data structures in both systems. | Q12: =_xlfn.CONCAT('1.3 IP Pairwise'!K45," ","-"," ",'1.3 IP Pairwise'!L45) -> L4 - Architectural Reorganization | R12: ='1.3 IP Pairwise'!M45 -> Refactoring that reorganizes architectural relationships between systems, requiring changes to how components interact across system boundaries and altering integration structures. | S12: ='1.3 IP Pairwise'!N45 -> Move Component, Reorganization | V12: =_xlfn.CONCAT('1.3 IP Pairwise'!K74," ","-"," ",'1.3 IP Pairwise'!L74) -> L4 - Strong Constraint | W12: ='1.3 IP Pairwise'!M74 -> The EA smell introduces dependency-driven constraints such that architectural elements depend on each other in a chain. Changes to one architectural element require coordinated updates to directly dependent architectural elements, with the impact propagating across multiple levels of dependency. | X12: ='1.3 IP Pairwise'!N74 -> The CRM system exposes an interface consumed by the ERP system, which relies on specific data fields. The ERP system provides this data to the Reporting system. Modifying the CRM interface (e.g., changing required data fields) requires updating the ERP system, which then requires updates in the Reporting system, causing the change to propagate across multiple dependent elements. | AA12: =_xlfn.CONCAT('1.3 IP Pairwise'!K103," ","-"," ",'1.3 IP Pairwise'!L103) -> L4 - High Coordination Overhead | AB12: ='1.3 IP Pairwise'!M103 -> The EA-smell instance creates coordination dependencies across multiple stakeholder groups and requires recurring involvement of formal architectural governance bodies to align or approve changes affecting the architectural condition (e.g., architecture review boards). | AC12: ='1.3 IP Pairwise'!N103 -> An enterprise application relies on vendor-specific database features, creating vendor lock-in. Removing the dependency requires introducing a database abstraction layer to decouple the application from vendor-specific functionality. The architectural and technology dependencies involved create coordination requirements between developers, infrastructure teams, and enterprise architects and require review and approval through architectural governance. | AF12: =_xlfn.CONCAT('1.3 IP Pairwise'!K132," ","-"," ",'1.3 IP Pairwise'!L132) -> L4 - High Impact | AG12: ='1.3 IP Pairwise'!M132 -> Failures associated with the EA smell cause disruptions that degrade business-critical capabilities (e.g., slower performance, reduced functionality, or intermittent failures) while the system remains operational. Recovery requires substantial operational effort. | AH12: ='1.3 IP Pairwise'!N132 -> Incidents associated with the EA smell result in degraded performance of a business-critical capability (e.g., slower response times or limited functionality), requiring repeated operational intervention, while the service remains available.
B13: 5 | C13: Vendor Lock-In | D13: 4 | E13: 5 | F13: 5 | G13: 5 | H13: 4 | I13: Dependence on a specific vendor imposes severe constraints on technology evolution and requires high coordination despite manageable migration effort. | L13: =_xlfn.CONCAT('1.3 IP Pairwise'!K17," ","-"," ",'1.3 IP Pairwise'!L17) -> L5 - Enterprise-Wide Scope | M13: ='1.3 IP Pairwise'!M17 -> Changes affect multiple systems or applications and require modifications to shared or common architectural elements used across systems (e.g., shared data models, integration platforms, or core services). | N13: ='1.3 IP Pairwise'!N17 -> Customer information is stored in a shared data model used by CRM, ERP, and Marketing systems. Resolving the issue requires modifying the shared data model, affecting all dependent systems. | Q13: =_xlfn.CONCAT('1.3 IP Pairwise'!K46," ","-"," ",'1.3 IP Pairwise'!L46) -> L5 - Architectural Layer Restructuring | R13: ='1.3 IP Pairwise'!M46 -> Refactoring that introduces, removes, or fundamentally restructures architectural layers or abstraction structures, significantly altering the overall architecture. | S13: ='1.3 IP Pairwise'!N46 -> Isolation Layer, Move Service to Different Layer | V13: =_xlfn.CONCAT('1.3 IP Pairwise'!K75," ","-"," ",'1.3 IP Pairwise'!L75) -> L5 - Severe Constraint | W13: ='1.3 IP Pairwise'!M75 -> The EA smell introduces dependency-driven constraints centered around a shared architectural element that is used by multiple architectural elements. Changes to the shared architectural element require simultaneous coordination across all dependent architectural elements, preventing independent architectural evolution. Consequently, future architectural evolution may require restructuring or replacement of the shared architectural element. | X13: ='1.3 IP Pairwise'!N75 -> The CRM, ERP, and Reporting systems rely on a shared data model that defines common data fields. Modifying the shared data model (e.g., changing required data fields) requires simultaneous updates across all dependent systems, preventing independent modification and requiring restructuring of the shared data model. | AA13: =_xlfn.CONCAT('1.3 IP Pairwise'!K104," ","-"," ",'1.3 IP Pairwise'!L104) -> L5 - Strategic Coordination Overhead | AB13: ='1.3 IP Pairwise'!M104 -> The EA-smell instance creates coordination dependencies across multiple organizational domains and stakeholder groups and requires strategic decisions or alignment from enterprise leadership or program sponsors (e.g., CIO, steering committee). | AC13: ='1.3 IP Pairwise'!N104 -> Several enterprise applications rely on a vendor-specific database platform, creating strong vendor lock-in. Eliminating the dependency would require migrating multiple systems to an alternative platform and redesigning parts of the application landscape. The resulting cross-system dependencies create coordination requirements across multiple organizational domains and affect the enterprise architecture roadmap, requiring strategic alignment and decisions by enterprise leadership or program sponsors. | AF13: =_xlfn.CONCAT('1.3 IP Pairwise'!K133," ","-"," ",'1.3 IP Pairwise'!L133) -> L5 - Critical Impact | AG13: ='1.3 IP Pairwise'!M133 -> Failures associated with the EA smell cannot be restored through normal operational actions and result in sustained unavailability of business-critical capabilities. | AH13: ='1.3 IP Pairwise'!N133 -> Persistent incidents associated with the EA smell result in the sustained unavailability of a business-critical capability, and the system cannot be restored through standard operational actions, requiring architectural redesign.
B14: 6
B15: 7
B16: 8
B17: 9
B18: 10

Sheet 1.5 Results EA Smell Dashboard
A1: EA SMELL PRIORITISATION DASHBOARD
B5: 1 | C5: CRITERIA WEIGHTS (GLOBAL) User-input weights defining the importance of each criterion.
E33: Criterion | F33: Subcriterion | G33: Local Weight | H33: Global Weight
E34: Remediation Effort | G34: ='1.7 AHP Calculations'!$F$18 -> 0.5 | H34: =Table1[[#This Row],[Local Weight]] -> 0.5
F35: Scope | G35: ='1.7 AHP Calculations'!$D$60 -> 0.5 | H35: =Table1[[#This Row],[Local Weight]]*$G$34 -> 0.25
F36: Restructuring Complexity | G36: ='1.7 AHP Calculations'!$D$61 -> 0.5 | H36: =Table1[[#This Row],[Local Weight]]*$G$34 -> 0.25
E37: Impact | G37: ='1.7 AHP Calculations'!$F$19 -> 0.5 | H37: =Table1[[#This Row],[Local Weight]] -> 0.5
F38: Evolution Constraint | G38: ='1.7 AHP Calculations'!$D$62 -> 0.33333333 | H38: =Table1[[#This Row],[Local Weight]]*$G$37 -> 0.16666667
F39: Governance & Coordination Overhead | G39: ='1.7 AHP Calculations'!$D$63 -> 0.33333333 | H39: =Table1[[#This Row],[Local Weight]]*$G$37 -> 0.16666667
F40: Operational Reliability Impact | G40: ='1.7 AHP Calculations'!$D$64 -> 0.33333333 | H40: =Table1[[#This Row],[Local Weight]]*$G$37 -> 0.16666667
E42: After changing the input data, select Data → Refresh All to update the tables below.
B44: 2 | C44: EA SMELL RATINGS User-provided ratings for each EA smell across all criteria. | E44: Rating (Intensity Priority): Rating assigned on the 1–5 scale, with its corresponding AHP-derived priority shown in parentheses.
E46: EA Smell Instance | F46: Scope Rating / Intensity Priority | G46: Restructuring Complexity Rating / Intensity Priority | H46: Evolution Constraint Rating / Intensity Priority | I46: Governance Overhead Rating / Intensity Priority | J46: Operational Reliability Rating / Intensity Priority
E47: Cyclic Dependency | F47: 4 (0.2231) | G47: 4 (0.1963) | H47: 4 (0.4076) | I47: 3 (0.2044) | J47: 3 (0.1915)
E48: Feature Envy | F48: 3 (0.3426) | G48: 3 (0.4757) | H48: 3 (0.1596) | I48: 2 (0.1141) | J48: 2 (0.0875)
E49: Shared Persistency | F49: 5 (0.0855) | G49: 3 (0.4757) | H49: 5 (1.0000) | I49: 4 (0.5362) | J49: 4 (0.5423)
E50: Stovepipe System | F50: 4 (0.2231) | G50: 4 (0.1963) | H50: 4 (0.4076) | I50: 3 (0.2044) | J50: 4 (0.5423)
E51: Vendor Lock-In | F51: 4 (0.2231) | G51: 5 (0.0856) | H51: 5 (1.0000) | I51: 5 (1.0000) | J51: 4 (0.5423)
E52: (blank)
B64: 3 | C64: FINAL RESULTS Computed weighted scores used to rank EA smells. | E64: How to read the results: Total is the weighted score for each EA smell instance, based on its ratings across the subcriteria. Normalized Priority is the normalized Total, showing the relative priority of each EA smell. Priority values sum to 1 (100%) and determine the final ranking.
E66: Rank | F66: EA Smell Instance | G66: Weighted Score / Total | H66: Normalized Priority
E67: 1 | F67: Vendor Lock-In | G67: 0.50089603 | H67: 0.28007762
E68: 2 | F68: Shared Persistency | G68: 0.48673056 | H68: 0.27215696
E69: 3 | F69: Stovepipe System | G69: 0.29722902 | H69: 0.16619656
E70: 4 | F70: Feature Envy | G70: 0.26479366 | H70: 0.14806023
E71: 5 | F71: Cyclic Dependency | G71: 0.23876932 | H71: 0.13350863
F72: (blank)

Sheet 1.6 IP Calculations
B1: Scope | J1: Restructuring Complexity | L1: Restructuring Complexity | T1: Evolution Constraint | V1: Evolution Constraint | AE1: Gov. and Coordination Overhead | AG1: Gov. & Coord. Overhead | AO1: Operational Reliability Impact | AQ1: Operational Reliability Impact
B3: Pairwise Comparison Matrix | L3: Pairwise Comparison Matrix | V3: Pairwise Comparison Matrix | AG3: Pairwise Comparison Matrix | AQ3: Pairwise Comparison Matrix
B5: Level | C5: L1 | D5: L2 | E5: L3 | F5: L4 | G5: L5 | L5: Level | M5: L1 | N5: L2 | O5: L3 | P5: L4 | Q5: L5 | V5: Level | W5: L1 | X5: L2 | Y5: L3 | Z5: L4 | AA5: L5 | AG5: Level | AH5: L1 | AI5: L2 | AJ5: L3 | AK5: L4 | AL5: L5 | AQ5: Level | AR5: L1 | AS5: L2 | AT5: L3 | AU5: L4 | AV5: L5
B6: L1 | C6: 1 | D6: =IF('1.3 IP Pairwise'!$G$13="",NA(),'1.3 IP Pairwise'!$G$13) -> 2 | E6: =IF('1.3 IP Pairwise'!$G$14="",NA(),'1.3 IP Pairwise'!$G$14) -> 3 | F6: =IF('1.3 IP Pairwise'!$G$15="",NA(),'1.3 IP Pairwise'!$G$15) -> 5 | G6: =IF('1.3 IP Pairwise'!$G$16="",NA(),'1.3 IP Pairwise'!$G$16) -> 7 | L6: L1 | M6: 1 | N6: =IF('1.3 IP Pairwise'!$G$42="",NA(),'1.3 IP Pairwise'!$G$42) -> 2 | O6: =IF('1.3 IP Pairwise'!$G$43="",NA(),'1.3 IP Pairwise'!$G$43) -> 3 | P6: =IF('1.3 IP Pairwise'!$G$44="",NA(),'1.3 IP Pairwise'!$G$44) -> 5 | Q6: =IF('1.3 IP Pairwise'!$G$45="",NA(),'1.3 IP Pairwise'!$G$45) -> 7 | V6: L1 | W6: 1 | X6: =IF('1.3 IP Pairwise'!$G$71="",NA(),'1.3 IP Pairwise'!$G$71) -> 0.5 | Y6: =IF('1.3 IP Pairwise'!$G$72="",NA(),'1.3 IP Pairwise'!$G$72) -> 0.33333333 | Z6: =IF('1.3 IP Pairwise'!$G$73="",NA(),'1.3 IP Pairwise'!$G$73) -> 0.2 | AA6: =IF('1.3 IP Pairwise'!$G$74="",NA(),'1.3 IP Pairwise'!$G$74) -> 0.11111111 | AG6: L1 | AH6: 1 | AI6: =IF('1.3 IP Pairwise'!$G$100="",NA(),'1.3 IP Pairwise'!$G$100) -> 0.33333333 | AJ6: =IF('1.3 IP Pairwise'!$G$101="",NA(),'1.3 IP Pairwise'!$G$101) -> 0.2 | AK6: =IF('1.3 IP Pairwise'!$G$102="",NA(),'1.3 IP Pairwise'!$G$102) -> 0.14285714 | AL6: =IF('1.3 IP Pairwise'!$G$103="",NA(),'1.3 IP Pairwise'!$G$103) -> 0.11111111 | AQ6: L1 | AR6: 1 | AS6: =IF('1.3 IP Pairwise'!$G$129="",NA(),'1.3 IP Pairwise'!$G$129) -> 0.5 | AT6: =IF('1.3 IP Pairwise'!$G$130="",NA(),'1.3 IP Pairwise'!$G$130) -> 0.2 | AU6: =IF('1.3 IP Pairwise'!$G$131="",NA(),'1.3 IP Pairwise'!$G$131) -> 0.14285714 | AV6: =IF('1.3 IP Pairwise'!$G$132="",NA(),'1.3 IP Pairwise'!$G$132) -> 0.11111111
B7: L2 | C7: =IFERROR(1/D6,NA()) -> 0.5 | D7: 1 | E7: =IF('1.3 IP Pairwise'!$G$17="",NA(),'1.3 IP Pairwise'!$G$17) -> 3 | F7: =IF('1.3 IP Pairwise'!$G$18="",NA(),'1.3 IP Pairwise'!$G$18) -> 5 | G7: =IF('1.3 IP Pairwise'!$G$19="",NA(),'1.3 IP Pairwise'!$G$19) -> 7 | L7: L2 | M7: =IFERROR(1/N6,NA()) -> 0.5 | N7: 1 | O7: =IF('1.3 IP Pairwise'!$G$46="",NA(),'1.3 IP Pairwise'!$G$46) -> 2 | P7: =IF('1.3 IP Pairwise'!$G$47="",NA(),'1.3 IP Pairwise'!$G$47) -> 5 | Q7: =IF('1.3 IP Pairwise'!$G$48="",NA(),'1.3 IP Pairwise'!$G$48) -> 7 | V7: L2 | W7: =IFERROR(1/X6,NA()) -> 2 | X7: 1 | Y7: =IF('1.3 IP Pairwise'!$G$75="",NA(),'1.3 IP Pairwise'!$G$75) -> 0.33333333 | Z7: =IF('1.3 IP Pairwise'!$G$76="",NA(),'1.3 IP Pairwise'!$G$76) -> 0.2 | AA7: =IF('1.3 IP Pairwise'!$G$77="",NA(),'1.3 IP Pairwise'!$G$77) -> 0.14285714 | AG7: L2 | AH7: =IFERROR(1/AI6,NA()) -> 3 | AI7: 1 | AJ7: =IF('1.3 IP Pairwise'!$G$104="",NA(),'1.3 IP Pairwise'!$G$104) -> 0.33333333 | AK7: =IF('1.3 IP Pairwise'!$G$105="",NA(),'1.3 IP Pairwise'!$G$105) -> 0.2 | AL7: =IF('1.3 IP Pairwise'!$G$106="",NA(),'1.3 IP Pairwise'!$G$106) -> 0.14285714 | AQ7: L2 | AR7: =IFERROR(1/AS6,NA()) -> 2 | AS7: 1 | AT7: =IF('1.3 IP Pairwise'!$G$133="",NA(),'1.3 IP Pairwise'!$G$133) -> 0.33333333 | AU7: =IF('1.3 IP Pairwise'!$G$134="",NA(),'1.3 IP Pairwise'!$G$134) -> 0.14285714 | AV7: =IF('1.3 IP Pairwise'!$G$135="",NA(),'1.3 IP Pairwise'!$G$135) -> 0.11111111
B8: L3 | C8: =IFERROR(1/E6,NA()) -> 0.33333333 | D8: =IFERROR(1/E7,NA()) -> 0.33333333 | E8: 1 | F8: =IF('1.3 IP Pairwise'!$G$20="",NA(),'1.3 IP Pairwise'!$G$20) -> 2 | G8: =IF('1.3 IP Pairwise'!$G$21="",NA(),'1.3 IP Pairwise'!$G$21) -> 5 | L8: L3 | M8: =IFERROR(1/O6,NA()) -> 0.33333333 | N8: =IFERROR(1/O7,NA()) -> 0.5 | O8: 1 | P8: =IF('1.3 IP Pairwise'!$G$49="",NA(),'1.3 IP Pairwise'!$G$49) -> 5 | Q8: =IF('1.3 IP Pairwise'!$G$50="",NA(),'1.3 IP Pairwise'!$G$50) -> 5 | V8: L3 | W8: =IFERROR(1/Y6,NA()) -> 3 | X8: =IFERROR(1/Y7,NA()) -> 3 | Y8: 1 | Z8: =IF('1.3 IP Pairwise'!$G$78="",NA(),'1.3 IP Pairwise'!$G$78) -> 0.2 | AA8: =IF('1.3 IP Pairwise'!$G$79="",NA(),'1.3 IP Pairwise'!$G$79) -> 0.14285714 | AG8: L3 | AH8: =IFERROR(1/AJ6,NA()) -> 5 | AI8: =IFERROR(1/AJ7,NA()) -> 3 | AJ8: 1 | AK8: =IF('1.3 IP Pairwise'!$G$107="",NA(),'1.3 IP Pairwise'!$G$107) -> 0.2 | AL8: =IF('1.3 IP Pairwise'!$G$108="",NA(),'1.3 IP Pairwise'!$G$108) -> 0.14285714 | AQ8: L3 | AR8: =IFERROR(1/AT6,NA()) -> 5 | AS8: =IFERROR(1/AT7,NA()) -> 3 | AT8: 1 | AU8: =IF('1.3 IP Pairwise'!$G$136="",NA(),'1.3 IP Pairwise'!$G$136) -> 0.2 | AV8: =IF('1.3 IP Pairwise'!$G$137="",NA(),'1.3 IP Pairwise'!$G$137) -> 0.14285714
B9: L4 | C9: =IFERROR(1/F6,NA()) -> 0.2 | D9: =IFERROR(1/F7,NA()) -> 0.2 | E9: =IFERROR(1/F8,NA()) -> 0.5 | F9: 1 | G9: =IF('1.3 IP Pairwise'!$G$22="",NA(),'1.3 IP Pairwise'!$G$22) -> 5 | L9: L4 | M9: =IFERROR(1/P6,NA()) -> 0.2 | N9: =IFERROR(1/P7,NA()) -> 0.2 | O9: =IFERROR(1/P8,NA()) -> 0.2 | P9: 1 | Q9: =IF('1.3 IP Pairwise'!$G$51="",NA(),'1.3 IP Pairwise'!$G$51) -> 5 | V9: L4 | W9: =IFERROR(1/Z6,NA()) -> 5 | X9: =IFERROR(1/Z7,NA()) -> 5 | Y9: =IFERROR(1/Z8,NA()) -> 5 | Z9: 1 | AA9: =IF('1.3 IP Pairwise'!$G$80="",NA(),'1.3 IP Pairwise'!$G$80) -> 0.2 | AG9: L4 | AH9: =IFERROR(1/AK6,NA()) -> 7 | AI9: =IFERROR(1/AK7,NA()) -> 5 | AJ9: =IFERROR(1/AK8,NA()) -> 5 | AK9: 1 | AL9: =IF('1.3 IP Pairwise'!$G$109="",NA(),'1.3 IP Pairwise'!$G$109) -> 0.33333333 | AQ9: L4 | AR9: =IFERROR(1/AU6,NA()) -> 7 | AS9: =IFERROR(1/AU7,NA()) -> 7 | AT9: =IFERROR(1/AU8,NA()) -> 5 | AU9: 1 | AV9: =IF('1.3 IP Pairwise'!$G$138="",NA(),'1.3 IP Pairwise'!$G$138) -> 0.33333333
B10: L5 | C10: =IFERROR(1/G6,NA()) -> 0.14285714 | D10: =IFERROR(1/G7,NA()) -> 0.14285714 | E10: =IFERROR(1/G8,NA()) -> 0.2 | F10: =IFERROR(1/G9,NA()) -> 0.2 | G10: 1 | L10: L5 | M10: =IFERROR(1/Q6,NA()) -> 0.14285714 | N10: =IFERROR(1/Q7,NA()) -> 0.14285714 | O10: =IFERROR(1/Q8,NA()) -> 0.2 | P10: =IFERROR(1/Q9,NA()) -> 0.2 | Q10: 1 | V10: L5 | W10: =IFERROR(1/AA6,NA()) -> 9 | X10: =IFERROR(1/AA7,NA()) -> 7 | Y10: =IFERROR(1/AA8,NA()) -> 7 | Z10: =IFERROR(1/AA9,NA()) -> 5 | AA10: 1 | AG10: L5 | AH10: =IFERROR(1/AL6,NA()) -> 9 | AI10: =IFERROR(1/AL7,NA()) -> 7 | AJ10: =IFERROR(1/AL8,NA()) -> 7 | AK10: =IFERROR(1/AL9,NA()) -> 3 | AL10: 1 | AQ10: L5 | AR10: =IFERROR(1/AV6,NA()) -> 9 | AS10: =IFERROR(1/AV7,NA()) -> 9 | AT10: =IFERROR(1/AV8,NA()) -> 7 | AU10: =IFERROR(1/AV9,NA()) -> 3 | AV10: 1
B11: col sum | C11: =SUM(C6:C10) -> 2.1761905 | D11: =SUM(D6:D10) -> 3.6761905 | E11: =SUM(E6:E10) -> 7.7 | F11: =SUM(F6:F10) -> 13.2 | G11: =SUM(G6:G10) -> 25 | L11: col sum | M11: =SUM(M6:M10) -> 2.1761905 | N11: =SUM(N6:N10) -> 3.8428571 | O11: =SUM(O6:O10) -> 6.4 | P11: =SUM(P6:P10) -> 16.2 | Q11: =SUM(Q6:Q10) -> 25 | V11: col sum | W11: =SUM(W6:W10) -> 20 | X11: =SUM(X6:X10) -> 16.5 | Y11: =SUM(Y6:Y10) -> 13.666667 | Z11: =SUM(Z6:Z10) -> 6.6 | AA11: =SUM(AA6:AA10) -> 1.5968254 | AG11: col sum | AH11: =SUM(AH6:AH10) -> 25 | AI11: =SUM(AI6:AI10) -> 16.333333 | AJ11: =SUM(AJ6:AJ10) -> 13.533333 | AK11: =SUM(AK6:AK10) -> 4.5428571 | AL11: =SUM(AL6:AL10) -> 1.7301587 | AQ11: col sum | AR11: =SUM(AR6:AR10) -> 24 | AS11: =SUM(AS6:AS10) -> 20.5 | AT11: =SUM(AT6:AT10) -> 13.533333 | AU11: =SUM(AU6:AU10) -> 4.4857143 | AV11: =SUM(AV6:AV10) -> 1.6984127
B13: Normalized Matrix | L13: Normalized Matrix | V13: Normalized Matrix | AG13: Normalized Matrix | AQ13: Normalized Matrix
B15: Level | C15: L1 | D15: L2 | E15: L3 | F15: L4 | G15: L5 | L15: Level | M15: L1 | N15: L2 | O15: L3 | P15: L4 | Q15: L5 | V15: Level | W15: L1 | X15: L2 | Y15: L3 | Z15: L4 | AA15: L5 | AG15: Level | AH15: L1 | AI15: L2 | AJ15: L3 | AK15: L4 | AL15: L5 | AQ15: Level | AR15: L1 | AS15: L2 | AT15: L3 | AU15: L4 | AV15: L5
